{
  "status": "failed",
  "exc_type": "BrokenPipeError",
  "message": "[Errno 32] Broken pipe",
  "traceback": "Traceback (most recent call last):\n  File \"/home/ubuntu/gogooku3-standalone/scripts/train_atft.py\", line 5442, in train\n    _ = run_phase_training(model, train_loader, val_loader, config, device)\n  File \"/home/ubuntu/gogooku3-standalone/scripts/train_atft.py\", line 1936, in run_phase_training\n    for batch_idx, batch in enumerate(train_loader):\n  File \"/usr/local/lib/python3.10/dist-packages/torch/utils/data/dataloader.py\", line 493, in __iter__\n    return self._get_iterator()\n  File \"/usr/local/lib/python3.10/dist-packages/torch/utils/data/dataloader.py\", line 424, in _get_iterator\n    return _MultiProcessingDataLoaderIter(self)\n  File \"/usr/local/lib/python3.10/dist-packages/torch/utils/data/dataloader.py\", line 1171, in __init__\n    w.start()\n  File \"/usr/lib/python3.10/multiprocessing/process.py\", line 121, in start\n    self._popen = self._Popen(self)\n  File \"/usr/lib/python3.10/multiprocessing/context.py\", line 224, in _Popen\n    return _default_context.get_context().Process._Popen(process_obj)\n  File \"/usr/lib/python3.10/multiprocessing/context.py\", line 281, in _Popen\n    return Popen(process_obj)\n  File \"/usr/lib/python3.10/multiprocessing/popen_fork.py\", line 16, in __init__\n    util._flush_std_streams()\n  File \"/usr/lib/python3.10/multiprocessing/util.py\", line 435, in _flush_std_streams\n    sys.stdout.flush()\nBrokenPipeError: [Errno 32] Broken pipe\n\nDuring handling of the above exception, another exception occurred:\n\nTraceback (most recent call last):\n  File \"/home/ubuntu/gogooku3-standalone/scripts/train_atft.py\", line 3891, in run_training\n    first_batch_probe(model, train_loader, device, n=3)\n  File \"/home/ubuntu/gogooku3-standalone/scripts/train_atft.py\", line 1079, in first_batch_probe\n    for i, batch in enumerate(dataloader):\n  File \"/usr/local/lib/python3.10/dist-packages/torch/utils/data/dataloader.py\", line 493, in __iter__\n    return self._get_iterator()\n  File \"/usr/local/lib/python3.10/dist-packages/torch/utils/data/dataloader.py\", line 424, in _get_iterator\n    return _MultiProcessingDataLoaderIter(self)\n  File \"/usr/local/lib/python3.10/dist-packages/torch/utils/data/dataloader.py\", line 1171, in __init__\n    w.start()\n  File \"/usr/lib/python3.10/multiprocessing/process.py\", line 121, in start\n    self._popen = self._Popen(self)\n  File \"/usr/lib/python3.10/multiprocessing/context.py\", line 224, in _Popen\n    return _default_context.get_context().Process._Popen(process_obj)\n  File \"/usr/lib/python3.10/multiprocessing/context.py\", line 281, in _Popen\n    return Popen(process_obj)\n  File \"/usr/lib/python3.10/multiprocessing/popen_fork.py\", line 16, in __init__\n    util._flush_std_streams()\n  File \"/usr/lib/python3.10/multiprocessing/util.py\", line 435, in _flush_std_streams\n    sys.stdout.flush()\nBrokenPipeError: [Errno 32] Broken pipe\n",
  "pid": 1070891,
  "time": 1757470191.0525594,
  "timestamp": "2025-09-10T11:09:51.052561+09:00",
  "tz": "Asia/Tokyo"
}